Workbook

Sheet Dashboard
B1: Retail Sales Dashboard — 2025
B2: Beginner-level analysis: 12 months, 4 regions, 4 categories, 12 products (synthetic dataset). All numbers update from the Clean Data sheet.
B4: TOTAL SALES | D4: TOTAL PROFIT | F4: PROFIT MARGIN | H4: ORDERS | J4: AVG ORDER VALUE | L4: PEAK MONTH
B5: =Analysis!E17 | D5: =Analysis!F17 | F5: =Analysis!G17 | H5: =Analysis!C17 | J5: =IFERROR(Analysis!E17/Analysis!C17,0) | L5: =INDEX(Analysis!A5:A16,MATCH(MAX(Analysis!E5:E16),Analysis!E5:E16,0))
B44: Key findings
B45: • Sales peak in Dec and are lowest in Aug; November and December together deliver 23% of annual sales, so the business is strongly seasonal.
B46: • Standing Desk is the top product by sales (₹11.7 lakh); the top 3 products contribute 38% of total sales. Desk Organizer is the weakest (₹2.8 lakh).
B47: • Furniture is the largest category by sales (33% share), while Accessories earns the best margin (39.0%) and Furniture the lowest (27.0%).
B48: • South is the strongest region (31% of sales) and East the weakest (15%).
B49: • Discounted orders earn a 28.4% margin versus 37.4% for full-price orders, so discounting has a real cost to profitability.
B51: See the Insights sheet for cleaning steps, metric choices and recommendations.

Sheet Analysis
A1: Sales Analysis (all figures are formulas on the Clean Data sheet)
A2: Currency: Indian Rupees (₹). Profit = Sales − Quantity × Unit Cost. Margin = Profit ÷ Sales.
A3: 1. Monthly trend
A4: Month | B4: Month # | C4: Orders | D4: Units | E4: Sales | F4: Profit | G4: Margin | H4: MoM Sales Growth
A5: Jan | B5: 1 | C5: =COUNTIFS('Clean Data'!$C$2:$C$1195,B5) | D5: =SUMIFS('Clean Data'!$G$2:$G$1195,'Clean Data'!$C$2:$C$1195,B5) | E5: =SUMIFS('Clean Data'!$K$2:$K$1195,'Clean Data'!$C$2:$C$1195,B5) | F5: =SUMIFS('Clean Data'!$L$2:$L$1195,'Clean Data'!$C$2:$C$1195,B5) | G5: =IFERROR(F5/E5,0) | H5: -
A6: Feb | B6: 2 | C6: =COUNTIFS('Clean Data'!$C$2:$C$1195,B6) | D6: =SUMIFS('Clean Data'!$G$2:$G$1195,'Clean Data'!$C$2:$C$1195,B6) | E6: =SUMIFS('Clean Data'!$K$2:$K$1195,'Clean Data'!$C$2:$C$1195,B6) | F6: =SUMIFS('Clean Data'!$L$2:$L$1195,'Clean Data'!$C$2:$C$1195,B6) | G6: =IFERROR(F6/E6,0) | H6: =IFERROR(E6/E5-1,0)
A7: Mar | B7: 3 | C7: =COUNTIFS('Clean Data'!$C$2:$C$1195,B7) | D7: =SUMIFS('Clean Data'!$G$2:$G$1195,'Clean Data'!$C$2:$C$1195,B7) | E7: =SUMIFS('Clean Data'!$K$2:$K$1195,'Clean Data'!$C$2:$C$1195,B7) | F7: =SUMIFS('Clean Data'!$L$2:$L$1195,'Clean Data'!$C$2:$C$1195,B7) | G7: =IFERROR(F7/E7,0) | H7: =IFERROR(E7/E6-1,0)
A8: Apr | B8: 4 | C8: =COUNTIFS('Clean Data'!$C$2:$C$1195,B8) | D8: =SUMIFS('Clean Data'!$G$2:$G$1195,'Clean Data'!$C$2:$C$1195,B8) | E8: =SUMIFS('Clean Data'!$K$2:$K$1195,'Clean Data'!$C$2:$C$1195,B8) | F8: =SUMIFS('Clean Data'!$L$2:$L$1195,'Clean Data'!$C$2:$C$1195,B8) | G8: =IFERROR(F8/E8,0) | H8: =IFERROR(E8/E7-1,0)
A9: May | B9: 5 | C9: =COUNTIFS('Clean Data'!$C$2:$C$1195,B9) | D9: =SUMIFS('Clean Data'!$G$2:$G$1195,'Clean Data'!$C$2:$C$1195,B9) | E9: =SUMIFS('Clean Data'!$K$2:$K$1195,'Clean Data'!$C$2:$C$1195,B9) | F9: =SUMIFS('Clean Data'!$L$2:$L$1195,'Clean Data'!$C$2:$C$1195,B9) | G9: =IFERROR(F9/E9,0) | H9: =IFERROR(E9/E8-1,0)
A10: Jun | B10: 6 | C10: =COUNTIFS('Clean Data'!$C$2:$C$1195,B10) | D10: =SUMIFS('Clean Data'!$G$2:$G$1195,'Clean Data'!$C$2:$C$1195,B10) | E10: =SUMIFS('Clean Data'!$K$2:$K$1195,'Clean Data'!$C$2:$C$1195,B10) | F10: =SUMIFS('Clean Data'!$L$2:$L$1195,'Clean Data'!$C$2:$C$1195,B10) | G10: =IFERROR(F10/E10,0) | H10: =IFERROR(E10/E9-1,0)
A11: Jul | B11: 7 | C11: =COUNTIFS('Clean Data'!$C$2:$C$1195,B11) | D11: =SUMIFS('Clean Data'!$G$2:$G$1195,'Clean Data'!$C$2:$C$1195,B11) | E11: =SUMIFS('Clean Data'!$K$2:$K$1195,'Clean Data'!$C$2:$C$1195,B11) | F11: =SUMIFS('Clean Data'!$L$2:$L$1195,'Clean Data'!$C$2:$C$1195,B11) | G11: =IFERROR(F11/E11,0) | H11: =IFERROR(E11/E10-1,0)
A12: Aug | B12: 8 | C12: =COUNTIFS('Clean Data'!$C$2:$C$1195,B12) | D12: =SUMIFS('Clean Data'!$G$2:$G$1195,'Clean Data'!$C$2:$C$1195,B12) | E12: =SUMIFS('Clean Data'!$K$2:$K$1195,'Clean Data'!$C$2:$C$1195,B12) | F12: =SUMIFS('Clean Data'!$L$2:$L$1195,'Clean Data'!$C$2:$C$1195,B12) | G12: =IFERROR(F12/E12,0) | H12: =IFERROR(E12/E11-1,0)
A13: Sep | B13: 9 | C13: =COUNTIFS('Clean Data'!$C$2:$C$1195,B13) | D13: =SUMIFS('Clean Data'!$G$2:$G$1195,'Clean Data'!$C$2:$C$1195,B13) | E13: =SUMIFS('Clean Data'!$K$2:$K$1195,'Clean Data'!$C$2:$C$1195,B13) | F13: =SUMIFS('Clean Data'!$L$2:$L$1195,'Clean Data'!$C$2:$C$1195,B13) | G13: =IFERROR(F13/E13,0) | H13: =IFERROR(E13/E12-1,0)
A14: Oct | B14: 10 | C14: =COUNTIFS('Clean Data'!$C$2:$C$1195,B14) | D14: =SUMIFS('Clean Data'!$G$2:$G$1195,'Clean Data'!$C$2:$C$1195,B14) | E14: =SUMIFS('Clean Data'!$K$2:$K$1195,'Clean Data'!$C$2:$C$1195,B14) | F14: =SUMIFS('Clean Data'!$L$2:$L$1195,'Clean Data'!$C$2:$C$1195,B14) | G14: =IFERROR(F14/E14,0) | H14: =IFERROR(E14/E13-1,0)
A15: Nov | B15: 11 | C15: =COUNTIFS('Clean Data'!$C$2:$C$1195,B15) | D15: =SUMIFS('Clean Data'!$G$2:$G$1195,'Clean Data'!$C$2:$C$1195,B15) | E15: =SUMIFS('Clean Data'!$K$2:$K$1195,'Clean Data'!$C$2:$C$1195,B15) | F15: =SUMIFS('Clean Data'!$L$2:$L$1195,'Clean Data'!$C$2:$C$1195,B15) | G15: =IFERROR(F15/E15,0) | H15: =IFERROR(E15/E14-1,0)
A16: Dec | B16: 12 | C16: =COUNTIFS('Clean Data'!$C$2:$C$1195,B16) | D16: =SUMIFS('Clean Data'!$G$2:$G$1195,'Clean Data'!$C$2:$C$1195,B16) | E16: =SUMIFS('Clean Data'!$K$2:$K$1195,'Clean Data'!$C$2:$C$1195,B16) | F16: =SUMIFS('Clean Data'!$L$2:$L$1195,'Clean Data'!$C$2:$C$1195,B16) | G16: =IFERROR(F16/E16,0) | H16: =IFERROR(E16/E15-1,0)
A17: Total | C17: =SUM(C5:C16) | D17: =SUM(D5:D16) | E17: =SUM(E5:E16) | F17: =SUM(F5:F16) | G17: =IFERROR(F17/E17,0)
A20: 2. Category performance
A21: Category | B21: Orders | C21: Units | D21: Sales | E21: Profit | F21: Margin | G21: Share of Sales
A22: Furniture | B22: =COUNTIFS('Clean Data'!$E$2:$E$1195,A22) | C22: =SUMIFS('Clean Data'!$G$2:$G$1195,'Clean Data'!$E$2:$E$1195,A22) | D22: =SUMIFS('Clean Data'!$K$2:$K$1195,'Clean Data'!$E$2:$E$1195,A22) | E22: =SUMIFS('Clean Data'!$L$2:$L$1195,'Clean Data'!$E$2:$E$1195,A22) | F22: =IFERROR(E22/D22,0) | G22: =IFERROR(D22/$D$26,0)
A23: Technology | B23: =COUNTIFS('Clean Data'!$E$2:$E$1195,A23) | C23: =SUMIFS('Clean Data'!$G$2:$G$1195,'Clean Data'!$E$2:$E$1195,A23) | D23: =SUMIFS('Clean Data'!$K$2:$K$1195,'Clean Data'!$E$2:$E$1195,A23) | E23: =SUMIFS('Clean Data'!$L$2:$L$1195,'Clean Data'!$E$2:$E$1195,A23) | F23: =IFERROR(E23/D23,0) | G23: =IFERROR(D23/$D$26,0)
A24: Accessories | B24: =COUNTIFS('Clean Data'!$E$2:$E$1195,A24) | C24: =SUMIFS('Clean Data'!$G$2:$G$1195,'Clean Data'!$E$2:$E$1195,A24) | D24: =SUMIFS('Clean Data'!$K$2:$K$1195,'Clean Data'!$E$2:$E$1195,A24) | E24: =SUMIFS('Clean Data'!$L$2:$L$1195,'Clean Data'!$E$2:$E$1195,A24) | F24: =IFERROR(E24/D24,0) | G24: =IFERROR(D24/$D$26,0)
A25: Office Supplies | B25: =COUNTIFS('Clean Data'!$E$2:$E$1195,A25) | C25: =SUMIFS('Clean Data'!$G$2:$G$1195,'Clean Data'!$E$2:$E$1195,A25) | D25: =SUMIFS('Clean Data'!$K$2:$K$1195,'Clean Data'!$E$2:$E$1195,A25) | E25: =SUMIFS('Clean Data'!$L$2:$L$1195,'Clean Data'!$E$2:$E$1195,A25) | F25: =IFERROR(E25/D25,0) | G25: =IFERROR(D25/$D$26,0)
A26: Total | B26: =SUM(B22:B25) | C26: =SUM(C22:C25) | D26: =SUM(D22:D25) | E26: =SUM(E22:E25) | F26: =IFERROR(E26/D26,0) | G26: =SUM(G22:G25)
A29: 3. Product performance (sorted by sales)
A30: Product | B30: Category | C30: Units | D30: Sales | E30: Profit | F30: Margin | G30: Sales Rank
A31: Standing Desk | B31: Furniture | C31: =SUMIFS('Clean Data'!$G$2:$G$1195,'Clean Data'!$F$2:$F$1195,A31) | D31: =SUMIFS('Clean Data'!$K$2:$K$1195,'Clean Data'!$F$2:$F$1195,A31) | E31: =SUMIFS('Clean Data'!$L$2:$L$1195,'Clean Data'!$F$2:$F$1195,A31) | F31: =IFERROR(E31/D31,0) | G31: =RANK(D31,$D$31:$D$42)
A32: Monitor 24" | B32: Technology | C32: =SUMIFS('Clean Data'!$G$2:$G$1195,'Clean Data'!$F$2:$F$1195,A32) | D32: =SUMIFS('Clean Data'!$K$2:$K$1195,'Clean Data'!$F$2:$F$1195,A32) | E32: =SUMIFS('Clean Data'!$L$2:$L$1195,'Clean Data'!$F$2:$F$1195,A32) | F32: =IFERROR(E32/D32,0) | G32: =RANK(D32,$D$31:$D$42)
A33: Printer Paper Box | B33: Office Supplies | C33: =SUMIFS('Clean Data'!$G$2:$G$1195,'Clean Data'!$F$2:$F$1195,A33) | D33: =SUMIFS('Clean Data'!$K$2:$K$1195,'Clean Data'!$F$2:$F$1195,A33) | E33: =SUMIFS('Clean Data'!$L$2:$L$1195,'Clean Data'!$F$2:$F$1195,A33) | F33: =IFERROR(E33/D33,0) | G33: =RANK(D33,$D$31:$D$42)
A34: Office Chair | B34: Furniture | C34: =SUMIFS('Clean Data'!$G$2:$G$1195,'Clean Data'!$F$2:$F$1195,A34) | D34: =SUMIFS('Clean Data'!$K$2:$K$1195,'Clean Data'!$F$2:$F$1195,A34) | E34: =SUMIFS('Clean Data'!$L$2:$L$1195,'Clean Data'!$F$2:$F$1195,A34) | F34: =IFERROR(E34/D34,0) | G34: =RANK(D34,$D$31:$D$42)
A35: Headphones | B35: Accessories | C35: =SUMIFS('Clean Data'!$G$2:$G$1195,'Clean Data'!$F$2:$F$1195,A35) | D35: =SUMIFS('Clean Data'!$K$2:$K$1195,'Clean Data'!$F$2:$F$1195,A35) | E35: =SUMIFS('Clean Data'!$L$2:$L$1195,'Clean Data'!$F$2:$F$1195,A35) | F35: =IFERROR(E35/D35,0) | G35: =RANK(D35,$D$31:$D$42)
A36: Bookshelf | B36: Furniture | C36: =SUMIFS('Clean Data'!$G$2:$G$1195,'Clean Data'!$F$2:$F$1195,A36) | D36: =SUMIFS('Clean Data'!$K$2:$K$1195,'Clean Data'!$F$2:$F$1195,A36) | E36: =SUMIFS('Clean Data'!$L$2:$L$1195,'Clean Data'!$F$2:$F$1195,A36) | F36: =IFERROR(E36/D36,0) | G36: =RANK(D36,$D$31:$D$42)
A37: Mechanical Keyboard | B37: Technology | C37: =SUMIFS('Clean Data'!$G$2:$G$1195,'Clean Data'!$F$2:$F$1195,A37) | D37: =SUMIFS('Clean Data'!$K$2:$K$1195,'Clean Data'!$F$2:$F$1195,A37) | E37: =SUMIFS('Clean Data'!$L$2:$L$1195,'Clean Data'!$F$2:$F$1195,A37) | F37: =IFERROR(E37/D37,0) | G37: =RANK(D37,$D$31:$D$42)
A38: Webcam | B38: Accessories | C38: =SUMIFS('Clean Data'!$G$2:$G$1195,'Clean Data'!$F$2:$F$1195,A38) | D38: =SUMIFS('Clean Data'!$K$2:$K$1195,'Clean Data'!$F$2:$F$1195,A38) | E38: =SUMIFS('Clean Data'!$L$2:$L$1195,'Clean Data'!$F$2:$F$1195,A38) | F38: =IFERROR(E38/D38,0) | G38: =RANK(D38,$D$31:$D$42)
A39: USB-C Hub | B39: Accessories | C39: =SUMIFS('Clean Data'!$G$2:$G$1195,'Clean Data'!$F$2:$F$1195,A39) | D39: =SUMIFS('Clean Data'!$K$2:$K$1195,'Clean Data'!$F$2:$F$1195,A39) | E39: =SUMIFS('Clean Data'!$L$2:$L$1195,'Clean Data'!$F$2:$F$1195,A39) | F39: =IFERROR(E39/D39,0) | G39: =RANK(D39,$D$31:$D$42)
A40: Wireless Mouse | B40: Technology | C40: =SUMIFS('Clean Data'!$G$2:$G$1195,'Clean Data'!$F$2:$F$1195,A40) | D40: =SUMIFS('Clean Data'!$K$2:$K$1195,'Clean Data'!$F$2:$F$1195,A40) | E40: =SUMIFS('Clean Data'!$L$2:$L$1195,'Clean Data'!$F$2:$F$1195,A40) | F40: =IFERROR(E40/D40,0) | G40: =RANK(D40,$D$31:$D$42)
A41: Notebook Set | B41: Office Supplies | C41: =SUMIFS('Clean Data'!$G$2:$G$1195,'Clean Data'!$F$2:$F$1195,A41) | D41: =SUMIFS('Clean Data'!$K$2:$K$1195,'Clean Data'!$F$2:$F$1195,A41) | E41: =SUMIFS('Clean Data'!$L$2:$L$1195,'Clean Data'!$F$2:$F$1195,A41) | F41: =IFERROR(E41/D41,0) | G41: =RANK(D41,$D$31:$D$42)
A42: Desk Organizer | B42: Office Supplies | C42: =SUMIFS('Clean Data'!$G$2:$G$1195,'Clean Data'!$F$2:$F$1195,A42) | D42: =SUMIFS('Clean Data'!$K$2:$K$1195,'Clean Data'!$F$2:$F$1195,A42) | E42: =SUMIFS('Clean Data'!$L$2:$L$1195,'Clean Data'!$F$2:$F$1195,A42) | F42: =IFERROR(E42/D42,0) | G42: =RANK(D42,$D$31:$D$42)
A45: 4. Regional performance
A46: Region | B46: Orders | C46: Sales | D46: Profit | E46: Margin | F46: Share of Sales
...

Sheet Insights
B1: Insights, Method and Data Notes
B3: About the dataset
B4: • Retail office-products sales, January to December 2025, 4 regions, 4 categories, 12 products.
B5: • IMPORTANT: this is a synthetic (simulated) dataset generated for this exercise, with deliberately messy raw data. Replace it with a real dataset (for example a public Superstore or Kaggle sales file) if your submission needs real-world data.
B7: Data cleaning log
B8: Step | C8: Rows affected | D8: Notes
B9: Raw records loaded | C9: 1230 | D9: Starting point: 1,230 rows incl. duplicates and blanks
B10: Exact duplicate rows removed | C10: 30 | D10: Same Order ID and identical values
B11: Rows dropped: missing Quantity | C11: 6 | D11: Sales cannot be computed without a quantity
B12: Missing Unit Price filled | C12: 15 | D12: Filled with the product's standard (most common) price
B13: Region labels standardised | C13: 140 | D13: Trimmed spaces and fixed upper/lower case
B14: Text dates converted to real dates | C14: 300 | D14: Format DD-Mon-YYYY converted to Excel dates
B15: Final clean records | C15: 1194 | D15: Rows used in all analysis
B17: Metrics chosen and why
B18: • Sales = Quantity × Unit Price × (1 − Discount): the revenue actually collected per order.
B19: • Profit and Margin: show which products earn money, not just which sell most.
B20: • Orders and Average Order Value: separate demand volume from basket size.
B21: • Month-over-month growth and share of sales: reveal seasonality and concentration.
B23: Dashboard structure
B24: • Top row: six headline KPIs. Below: monthly trend (time), category (group), product (detail), region (geography). Each chart answers one business question and reads from the Analysis sheet, which reads from Clean Data via formulas.
B26: Key findings
B27: • Sales peak in Dec and are lowest in Aug; November and December together deliver 23% of annual sales, so the business is strongly seasonal.
B28: • Standing Desk is the top product by sales (₹11.7 lakh); the top 3 products contribute 38% of total sales. Desk Organizer is the weakest (₹2.8 lakh).
B29: • Furniture is the largest category by sales (33% share), while Accessories earns the best margin (39.0%) and Furniture the lowest (27.0%).
B30: • South is the strongest region (31% of sales) and East the weakest (15%).
... B38: • Set a discount cap for low-margin categories so promotions do not push orders below the target margin.

Sheet Clean Data
A1: Order ID | B1: Order Date | C1: Month | D1: Region | E1: Category | F1: Product | G1: Quantity | H1: Unit Price | I1: Discount | J1: Unit Cost | K1: Sales | L1: Profit
A2: ORD-10874 | B2: 45658 | C2: =MONTH(B2) | D2: West | E2: Technology | F2: Mechanical Keyboard | G2: 3 | H2: 4200 | I2: 0.15 | J2: 2500 | K2: =G2*H2*(1-I2) | L2: =K2-G2*J2
A3: ORD-10004 | B3: 45659 | C3: =MONTH(B3) | D3: North | E3: Accessories | F3: Webcam | G3: 1 | H3: 3200 | I3: 0 | J3: 1900 | K3: =G3*H3*(1-I3) | L3: =K3-G3*J3
A4: ORD-10244 | B4: 45659 | C4: =MONTH(B4) | D4: West | E4: Technology | F4: Mechanical Keyboard | G4: 1 | H4: 4200 | I4: 0.1 | J4: 2500 | K4: =G4*H4*(1-I4) | L4: =K4-G4*J4
A5: ORD-10728 | B5: 45659 | C5: =MONTH(B5) | D5: South | E5: Accessories | F5: Headphones | G5: 2 | H5: 4500 | I5: 0.05 | J5: 2600 | K5: =G5*H5*(1-I5) | L5: =K5-G5*J5
A6: ORD-10789 | B6: 45660 | C6: =MONTH(B6) | D6: South | E6: Office Supplies | F6: Printer Paper Box | G6: 4 | H6: 1600 | I6: 0 | J6: 1050 | K6: =G6*H6*(1-I6) | L6: =K6-G6*J6
A7: ORD-10898 | B7: 45660 | C7: =MONTH(B7) | D7: South | E7: Furniture | F7: Standing Desk | G7: 2 | H7: 19500 | I7: 0 | J7: 13800 | K7: =G7*H7*(1-I7) | L7: =K7-G7*J7
A8: ORD-10157 | B8: 45661 | C8: =MONTH(B8) | D8: West | E8: Accessories | F8: Headphones | G8: 3 | H8: 4500 | I8: 0 | J8: 2600 | K8: =G8*H8*(1-I8) | L8: =K8-G8*J8
A9: ORD-10877 | B9: 45661 | C9: =MONTH(B9) | D9: South | E9: Technology | F9: Wireless Mouse | G9: 4 | H9: 1200 | I9: 0 | J9: 650 | K9: =G9*H9*(1-I9) | L9: =K9-G9*J9
A10: ORD-10891 | B10: 45661 | C10: =MONTH(B10) | D10: West | E10: Accessories | F10: Webcam | G10: 2 | H10: 3200 | I10: 0 | J10: 1900 | K10: =G10*H10*(1-I10) | L10: =K10-G10*J10
A11: ORD-10051 | B11: 45662 | C11: =MONTH(B11) | D11: South | E11: Office Supplies | F11: Printer Paper Box | G11: 6 | H11: 1600 | I11: 0.2 | J11: 1050 | K11: =G11*H11*(1-I11) | L11: =K11-G11*J11
A12: ORD-10315 | B12: 45662 | C12: =MONTH(B12) | D12: South | E12: Technology | F12: Wireless Mouse | G12: 1 | H12: 1200 | I12: 0 | J12: 650 | K12: =G12*H12*(1-I12) | L12: =K12-G12*J12
A13: ORD-10469 | B13: 45662 | C13: =MONTH(B13) | D13: West | E13: Accessories | F13: Webcam | G13: 2 | H13: 3200 | I13: 0 | J13: 1900 | K13: =G13*H13*(1-I13) | L13: =K13-G13*J13
... A1195: ORD-10552 | B1195: 46019 | C1195: =MONTH(B1195) | D1195: West | E1195: Accessories | F1195: Headphones | G1195: 3 | H1195: 4500 | I1195: 0.15 | J1195: 2600 | K1195: =G1195*H1195*(1-I1195) | L1195: =K1195-G1195*J1195

Sheet Raw Data
A1: Order ID | B1: Order Date | C1: Region | D1: Category | E1: Product | F1: Quantity | G1: Unit Price | H1: Discount | I1: Unit Cost
A2: ORD-10582 | B2: 08-May-2025 | C2: West | D2: Office Supplies | E2: Desk Organizer | F2: 1 | G2: 850 | H2: 0 | I2: 420
A3: ORD-11076 | B3: 24-May-2025 | C3: south | D3: Technology | E3: Wireless Mouse | F3: 5 | G3: 1200 | H3: 0 | I3: 650
A4: ORD-11129 | B4: 45877 | C4: West | D4: Office Supplies | E4: Notebook Set | F4: 7 | G4: 450 | H4: 0.05 | I4: 190
A5: ORD-10986 | B5: 45664 | C5: North | D5: Accessories | E5: USB-C Hub | F5: 2 | G5: 1800 | H5: 0.15 | I5: 980
A6: ORD-10635 | B6: 45908 | C6: East | D6: Technology | E6: Mechanical Keyboard | F6: 2 | G6: 4200 | H6: 0 | I6: 2500
A7: ORD-10724 | B7: 45949 | C7: East | D7: Accessories | E7: USB-C Hub | F7: 4 | G7: 1800 | H7: 0 | I7: 980
A8: ORD-10123 | B8: 45665 | C8: West | D8: Accessories | E8: Headphones | F8: 1 | G8: 4500 | H8: 0 | I8: 2600
A9: ORD-10445 | B9: 45693 | C9: North | D9: Technology | E9: Wireless Mouse | F9: 5 | G9: 1200 | H9: 0.2 | I9: 650
A10: ORD-10142 | B10: 45817 | C10: North | D10: Furniture | E10: Bookshelf | F10: 2 | G10: 6200 | H10: 0.2 | I10: 4100
A11: ORD-10524 | B11: 45755 | C11: East | D11: Furniture | E11: Office Chair | F11: 2 | G11: 8500 | H11: 0.05 | I11: 5600
A12: ORD-10099 | B12: 45945 | C12: West | D12: Accessories | E12: Webcam | F12: 2 | G12: 3200 | H12: 0.05 | I12: 1900
A13: ORD-11099 | B13: 45843 | C13: East | D13: Accessories | E13: Webcam | F13: 1 | G13: 3200 | H13: 0.2 | I13: 1900
A14: ORD-10978 | B14: 07-Dec-2025 | C14: West | D14: Accessories | E14: Headphones | F14: 3 | G14: 4500 | H14: 0.1 | I14: 2600
A15: ORD-10546 | B15: 46002 | C15: West | D15: Office Supplies | E15: Printer Paper Box | F15: 3 | G15: 1600 | H15: 0.2 | I15: 1050
A16: ORD-10012 | B16: 45790 | C16: West | D16: Technology | E16: Monitor 24" | F16: 1 | G16: 11500 | H16: 0.05 | I16: 8200
A17: ORD-10880 | B17: 45697 | C17: East | D17: Office Supplies | E17: Printer Paper Box | F17: 2 | G17: 1600 | H17: 0 | I17: 1050
A18: ORD-10264 | B18: 45823 | C18: West | D18: Technology | E18: Mechanical Keyboard | F18: 2 | G18: 4200 | H18: 0 | I18: 2500
A19: ORD-10688 | B19: 45761 | C19: North | D19: Accessories | E19: Webcam | F19: 1 | G19: 3200 | H19: 0 | I19: 1900
A20: ORD-10520 | B20: 45704 | C20: South | D20: Technology | E20: Mechanical Keyboard | F20: 3 | G20: 4200 | H20: 0.15 | I20: 2500
A21: ORD-10499 | B21: 46009 | C21: EAST | D21: Furniture | E21: Bookshelf | F21: 1 | G21: 6200 | H21: 0.1 | I21: 4100
A22: ORD-10836 | B22: 45835 | C22: North | D22: Accessories | E22: Webcam | F22: 1 | G22: 3200 | H22: 0 | I22: 1900
A23: ORD-10937 | B23: 45885 | C23: West | D23: Accessories | E23: USB-C Hub | F23: 4 | G23: 1800 | H23: 0 | I23: 980
A24: ORD-10089 | B24: 27-Oct-2025 | C24: South | D24: Technology | E24: Monitor 24" | F24: 2 | G24: 11500 | H24: 0 | I24: 8200
A25: ORD-10177 | B25: 45901 | C25: North | D25: Technology | E25: Wireless Mouse | F25: 1 | G25: 1200 | H25: 0.05 | I25: 650
A26: ORD-10783 | B26: 45978 | C26: East | D26: Office Supplies | E26: Notebook Set | F26: 7 | G26: 450 | H26: 0.15 | I26: 190
A27: ORD-10606 | B27: 45845 | C27: North | D27: Office Supplies | E27: Notebook Set | F27: 4 | G27: 450 | H27: 0.2 | I27: 190
A28: ORD-10999 | B28: 45998 | C28: South | D28: Furniture | E28: Standing Desk | F28: 2 | G28: 19500 | H28: 0 | I28: 13800
A29: ORD-10034 | B29: 45740 | C29: South | D29: Accessories | E29: USB-C Hub | F29: 3 | G29: 1800 | H29: 0 | I29: 980
A30: ORD-10416 | B30: 45774 | C30: East | D30: Office Supplies | E30: Notebook Set | F30: 8 | H30: 0 | I30: 190
A31: ORD-10820 | B31: 17-Dec-2025 | C31: North | D31: Accessories | E31: Headphones | F31: 1 | G31: 4500 | H31: 0.15 | I31: 2600
A32: ORD-10388 | B32: 45962 | C32: North | D32: Technology | E32: Wireless Mouse | F32: 3 | G32: 1200 | H32: 0.05 | I32: 650
A33: ORD-10158 | B33: 45980 | C33: West | D33: Office Supplies | E33: Desk Organizer | F33: 4 | G33: 850 | H33: 0.15 | I33: 420
A34: ORD-10917 | B34: 20-Sep-2025 | C34: North | D34: Office Supplies | E34: Desk Organizer | F34: 5 | G34: 850 | H34: 0.15 | I34: 420
A35: ORD-11035 | B35: 45730 | C35: West | D35: Technology | E35: Mechanical Keyboard | F35: 1 | G35: 4200 | H35: 0 | I35: 2500
A36: ORD-10358 | B36: 45832 | C36: South | D36: Accessories | E36: Headphones | F36: 2 | G36: 4500 | H36: 0 | I36: 2600
A37: ORD-10151 | B37: 45669 | C37: West | D37: Office Supplies | E37: Notebook Set | F37: 4 | G37: 450 | H37: 0 | I37: 190
A38: ORD-10892 | B38: 14-Jul-2025 | C38: East | D38: Office Supplies | E38: Printer Paper Box | F38: 6 | G38: 1600 | H38: 0.05 | I38: 1050
A39: ORD-10616 | B39: 46009 | C39: South | D39: Technology | E39: Wireless Mouse | F39: 5 | G39: 1200 | H39: 0.15 | I39: 650
A40: ORD-10949 | B40: 45920 | C40: South | D40: Technology | E40: Wireless Mouse | F40: 5 | G40: 1200 | H40: 0.05 | I40: 650
...
